<?xml version="1.0" encoding="utf-8"?>
<!-- This URDF was automatically created by SolidWorks to URDF Exporter! Originally created by Stephen Brawner (brawner@gmail.com) 
     Commit Version: 1.6.0-1-g15f4949  Build Version: 1.6.7594.29634
     For more information, please see http://wiki.ros.org/sw_urdf_exporter -->
<robot
  name="bottleBot_description">
  <link
    name="base_link">
    <inertial>
      <origin
        xyz="-0.0139744593731478 0.0109514707558618 0.159290409867361"
        rpy="0 0 0" />
      <mass
        value="0.763096236233645" />
      <inertia
        ixx="0.00110852256384707"
        ixy="2.44534980372812E-11"
        ixz="-7.7332712921807E-11"
        iyy="0.000950092672162934"
        iyz="6.38622198180867E-06"
        izz="0.00111374448220001" />
    </inertial>
    <visual>
      <origin
        xyz="0 0 0"
        rpy="0 0 0" />
      <geometry>
        <mesh
          filename="package://bottleBot_description/meshes/base_link.STL" />
      </geometry>
      <material
        name="">
        <color
          rgba="0.752941176470588 0.752941176470588 1 1" />
      </material>
    </visual>
    <collision>
      <origin
        xyz="0 0 0"
        rpy="0 0 0" />
      <geometry>
        <mesh
          filename="package://bottleBot_description/meshes/base_link.STL" />
      </geometry>
    </collision>
  </link>
  <link
    name="right_link">
    <inertial>
      <origin
        xyz="-0.0125 3.4694E-18 0"
        rpy="0 0 0" />
      <mass
        value="0.021692" />
      <inertia
        ixx="3.3737E-06"
        ixy="-4.0849E-39"
        ixz="-1.2044E-38"
        iyy="2.7308E-06"
        iyz="7.6788E-41"
        izz="2.7308E-06" />
    </inertial>
    <visual>
      <origin
        xyz="0 0 0"
        rpy="0 0 0" />
      <geometry>
        <mesh
          filename="package://bottleBot_description/meshes/right_link.STL" />
      </geometry>
      <material
        name="">
        <color
          rgba="0.25098 0.25098 0.25098 1" />
      </material>
    </visual>
    <collision>
      <origin
        xyz="0 0 0"
        rpy="0 0 0" />
      <geometry>
        <mesh
          filename="package://bottleBot_description/meshes/right_link.STL" />
      </geometry>
    </collision>
  </link>
  <joint
    name="right_joint"
    type="continuous">
    <origin
      xyz="0 -0.055 0.01"
      rpy="1.5708 0 1.5708" />
    <parent
      link="base_link" />
    <child
      link="right_link" />
    <axis
      xyz="1 0 0" />
  </joint>
  <link
    name="left_link">
    <inertial>
      <origin
        xyz="-0.0125 3.4694E-18 0"
        rpy="0 0 0" />
      <mass
        value="0.021692" />
      <inertia
        ixx="3.3737E-06"
        ixy="-4.0849E-39"
        ixz="-1.2044E-38"
        iyy="2.7308E-06"
        iyz="7.6788E-41"
        izz="2.7308E-06" />
    </inertial>
    <visual>
      <origin
        xyz="0 0 0"
        rpy="0 0 0" />
      <geometry>
        <mesh
          filename="package://bottleBot_description/meshes/left_link.STL" />
      </geometry>
      <material
        name="">
        <color
          rgba="1 1 1 1" />
      </material>
    </visual>
    <collision>
      <origin
        xyz="0 0 0"
        rpy="0 0 0" />
      <geometry>
        <mesh
          filename="package://bottleBot_description/meshes/left_link.STL" />
      </geometry>
    </collision>
  </link>
  <joint
    name="left_joint"
    type="continuous">
    <origin
      xyz="0 0.055 0.01"
      rpy="1.5708 0 1.5708" />
    <parent
      link="base_link" />
    <child
      link="left_link" />
    <axis
      xyz="1 0 0" />
  </joint>
</robot>